# Task Management and Cancellation in Python asyncio

Asyncio is Python's built-in library for writing concurrent code using the async/await syntax. At its core, asyncio revolves around managing tasks - units of work that can be scheduled, executed, monitored, and cancelled. Let's explore how tasks work and how cancellation operates within the asyncio framework, building our understanding from first principles.

## First Principles: What is a Task?

At the most fundamental level, a task in asyncio represents a unit of work that can run independently. More specifically, a task is a wrapper around a coroutine that schedules it for execution on the event loop.

To understand tasks, we first need to understand coroutines:

A coroutine is a special function defined with `async def` that can pause its execution with `await`, allowing other code to run while waiting for something (like I/O).

```python
async def example_coroutine():
    print("Starting work")
    await asyncio.sleep(1)  # Pause here, allowing other code to run
    print("Work completed")
```

While a coroutine defines what work should be done, a task is what enables that work to be scheduled, managed, and monitored by the event loop.

## Creating Tasks

There are several ways to create tasks:

1. Using `asyncio.create_task()`:

```python
async def main():
    # Create a task from a coroutine
    task = asyncio.create_task(example_coroutine())
  
    # The task starts executing immediately
    # We can do other work here
  
    # Wait for the task to complete
    await task
```

2. Using `loop.create_task()`:

```python
async def main():
    loop = asyncio.get_running_loop()
    task = loop.create_task(example_coroutine())
    await task
```

3. Using `asyncio.ensure_future()` (older method):

```python
async def main():
    task = asyncio.ensure_future(example_coroutine())
    await task
```

When you create a task, it's scheduled to run as soon as possible. The task maintains state information about the coroutine's execution, including:

* Whether it's pending, running, done, or cancelled
* Its result or exception if completed
* Callbacks to be called when the task finishes

## Task States

A task can be in one of these states:

1. **Pending** : The task has been created but hasn't completed execution
2. **Running** : The task is currently executing
3. **Done** : The task has completed execution (either with a result, exception, or by being cancelled)
4. **Cancelled** : The task was cancelled before completion

You can check a task's state:

```python
async def main():
    task = asyncio.create_task(example_coroutine())
  
    print(task.done())      # False - task is still pending
    print(task.cancelled()) # False - task hasn't been cancelled
  
    await task
  
    print(task.done())      # True - task is now done
```

## Task Cancellation

Now let's delve into the heart of our topic: how task cancellation works in asyncio.

### Basic Cancellation

At its simplest, you can cancel a task by calling its `cancel()` method:

```python
async def main():
    task = asyncio.create_task(example_coroutine())
  
    # Cancel the task
    task.cancel()
  
    try:
        # Await the cancelled task
        await task
    except asyncio.CancelledError:
        print("Task was cancelled")
```

When you cancel a task:

1. The task's state changes to "cancelled"
2. A `CancelledError` is injected into the coroutine at the next suitable opportunity
3. This exception propagates up to whoever is awaiting the task

### The Cancellation Process in Detail

Cancellation in asyncio is cooperative, meaning:

1. You request a task to cancel by calling `task.cancel()`
2. The task isn't immediately stopped - it continues until it reaches an await point
3. At the await point, the event loop injects a `CancelledError`
4. The coroutine can either:
   * Let the exception propagate (typical case)
   * Catch the exception and decide what to do

Here's what this looks like in practice:

```python
async def cancellable_work():
    try:
        print("Starting work")
        # An await point where cancellation can happen
        await asyncio.sleep(5)
        print("Work completed")
        return "Result"
    except asyncio.CancelledError:
        print("Work was cancelled during sleep")
        # Re-raise to propagate the cancellation
        raise
      
async def main():
    task = asyncio.create_task(cancellable_work())
  
    # Let the task start
    await asyncio.sleep(1)
  
    # Request cancellation
    task.cancel()
  
    try:
        # Wait for the task to deal with cancellation
        result = await task
        print(f"Got result: {result}")
    except asyncio.CancelledError:
        print("Main: task was indeed cancelled")
```

When you run this, you'll see:

```
Starting work
Work was cancelled during sleep
Main: task was indeed cancelled
```

### Handling Cancellation

One of the powerful aspects of asyncio's cancellation mechanism is that you can handle cancellations within your coroutines. This allows for cleaning up resources when a task is cancelled:

```python
async def clean_cancellation():
    try:
        print("Starting work with resources")
        await asyncio.sleep(5)
        print("Work completed")
        return "Success"
    except asyncio.CancelledError:
        print("Cleaning up resources before cancellation")
        # Do cleanup work here
        # Then re-raise to signal that we were indeed cancelled
        raise
```

Sometimes, you might want to suppress a cancellation and complete a task anyway:

```python
async def suppressing_cancellation():
    try:
        print("Starting critical work")
        await asyncio.sleep(5)
        print("Critical work completed")
        return "Critical result"
    except asyncio.CancelledError:
        print("Cancellation requested, but finishing the critical work anyway")
        # Complete the critical work synchronously
        time.sleep(1)  # Simulating critical cleanup
        print("Critical work properly finished despite cancellation")
        return "Emergency result"
```

Be cautious with this approach! Suppressing cancellation can lead to tasks that refuse to stop when asked, which can cause resource leaks or prevent clean application shutdown.

## Timeouts and Cancellation

A common use case for cancellation is implementing timeouts. Asyncio provides `asyncio.wait_for()` for this purpose:

```python
async def slow_operation():
    await asyncio.sleep(10)
    return "Finished eventually"

async def main():
    try:
        # Will cancel slow_operation() after 2 seconds
        result = await asyncio.wait_for(slow_operation(), timeout=2)
        print(result)
    except asyncio.TimeoutError:
        print("Operation timed out")
```

Behind the scenes, `wait_for()`:

1. Creates a task for your coroutine
2. Waits for it to complete or for the timeout
3. If timeout occurs, cancels the task
4. Raises `TimeoutError` instead of `CancelledError`

## Shield - Protecting Tasks from Cancellation

Sometimes you want to protect a task from cancellation. The `asyncio.shield()` function does this:

```python
async def main():
    try:
        # Outer task can be cancelled, but inner_operation is protected
        task = asyncio.create_task(
            asyncio.shield(inner_operation())
        )
      
        # Will cancel the outer task but not inner_operation
        task.cancel()
        await task
    except asyncio.CancelledError:
        print("Outer task cancelled, but inner operation continues")
```

The `shield()` function creates a protective layer around a coroutine, preventing cancellation signals from reaching it.

## Advanced Task Management

### Waiting for Multiple Tasks

Asyncio provides several functions for working with multiple tasks:

1. `asyncio.gather()` - Run tasks concurrently and collect their results:

```python
async def main():
    # Start all tasks concurrently
    results = await asyncio.gather(
        asyncio.sleep(1, result="Task 1"),
        asyncio.sleep(2, result="Task 2"),
        asyncio.sleep(3, result="Task 3")
    )
    print(results)  # ['Task 1', 'Task 2', 'Task 3']
```

2. `asyncio.wait()` - Wait for tasks with more control:

```python
async def main():
    task1 = asyncio.create_task(asyncio.sleep(1))
    task2 = asyncio.create_task(asyncio.sleep(2))
    task3 = asyncio.create_task(asyncio.sleep(3))
  
    # Wait for tasks to complete or for timeout
    done, pending = await asyncio.wait(
        [task1, task2, task3],
        timeout=1.5,
        return_when=asyncio.FIRST_COMPLETED
    )
  
    print(f"Completed tasks: {len(done)}")
    print(f"Pending tasks: {len(pending)}")
  
    # Cancel remaining tasks
    for task in pending:
        task.cancel()
```

### Task Groups (Python 3.11+)

Python 3.11 introduced TaskGroup, a context manager for managing related tasks:

```python
async def main():
    async with asyncio.TaskGroup() as tg:
        task1 = tg.create_task(asyncio.sleep(1))
        task2 = tg.create_task(asyncio.sleep(2))
        task3 = tg.create_task(asyncio.sleep(3))
      
    # All tasks are now complete or cancelled
    # If any task raised an exception, it would be propagated here
```

TaskGroup provides several benefits:

* Automatic cleanup of all child tasks if the context exits
* Exception propagation from child tasks
* Clear task hierarchy and lifetimes

## Real-World Examples

### Example 1: Web Scraping with Timeout

```python
async def fetch_url(session, url, timeout=10):
    try:
        async with session.get(url, timeout=timeout) as response:
            return await response.text()
    except asyncio.TimeoutError:
        print(f"Fetching {url} timed out")
        return None
    except asyncio.CancelledError:
        print(f"Fetching {url} was cancelled")
        raise
    except Exception as e:
        print(f"Error fetching {url}: {e}")
        return None

async def scrape_sites():
    async with aiohttp.ClientSession() as session:
        tasks = [
            fetch_url(session, "https://example.com"),
            fetch_url(session, "https://python.org"),
            fetch_url(session, "https://slow-website.com", timeout=5)
        ]
      
        results = await asyncio.gather(*tasks, return_exceptions=True)
      
        for url, result in zip(["example.com", "python.org", "slow-website.com"], results):
            if isinstance(result, Exception):
                print(f"{url}: Failed with {type(result).__name__}")
            else:
                print(f"{url}: Successfully fetched {len(result)} bytes")
```

This example shows how we handle timeouts and cancellations in a practical web scraping scenario.

### Example 2: Graceful Shutdown

```python
import asyncio
import signal

async def worker(name):
    try:
        while True:
            print(f"Worker {name} doing work")
            await asyncio.sleep(1)
    except asyncio.CancelledError:
        print(f"Worker {name} shutting down gracefully")
        # Cleanup code here
        raise

async def main():
    # Start workers
    workers = [
        asyncio.create_task(worker(f"worker-{i}"))
        for i in range(3)
    ]
  
    # Setup signal handlers for graceful shutdown
    loop = asyncio.get_running_loop()
    for sig in (signal.SIGINT, signal.SIGTERM):
        loop.add_signal_handler(sig, lambda s=sig: asyncio.create_task(shutdown(s, workers)))
  
    # Wait for workers or shutdown
    await asyncio.gather(*workers, return_exceptions=True)
  
async def shutdown(signal, workers):
    print(f"Received signal {signal.name}, shutting down...")
    # Cancel all worker tasks
    for worker in workers:
        worker.cancel()
  
    # Wait for all workers to complete their cleanup
    await asyncio.gather(*workers, return_exceptions=True)
  
    # Stop the event loop
    loop = asyncio.get_running_loop()
    loop.stop()

if __name__ == "__main__":
    asyncio.run(main())
```

This example shows how to implement a graceful shutdown pattern where we cancel tasks when receiving termination signals.

## Understanding Cancellation Internals

To deeply understand asyncio cancellation, we need to look at what happens inside the event loop:

1. When you call `task.cancel()`, the task is marked as cancelled, but it's not immediately stopped
2. The event loop continues running all scheduled callbacks
3. When the coroutine reaches an await point, the event loop checks if the task is marked for cancellation
4. If it is, instead of resuming the coroutine normally, it throws a `CancelledError` into it
5. This exception propagates through the coroutine stack until it's caught or reaches the top level

The key insight is that cancellation only happens at await points. This means:

```python
async def uncancellable_section():
    # Task can't be cancelled during this section!
    for i in range(10000000):
        x = i * i  # CPU-bound work with no await
  
    # Cancellation can only happen here
    await asyncio.sleep(0)
  
    # More code
```

If you have long-running CPU-bound code without any await points, that section cannot be cancelled until the next await. This is why it's important to add strategic await points in compute-heavy asyncio code.

## Common Pitfalls with Cancellation

### 1. Ignoring CancelledError

```python
async def problematic():
    try:
        await asyncio.sleep(10)
    except asyncio.CancelledError:
        print("Cancelled, but ignoring it")
        # Not re-raising - BAD!
  
    # More code that will still run despite cancellation
    print("This will still execute!")
```

If you catch `CancelledError` and don't re-raise it, the task will continue running despite cancellation, which can lead to surprising behavior and resource leaks.

### 2. Cancelling Tasks Without Awaiting Them

```python
async def main():
    task = asyncio.create_task(long_running_work())
  
    # Later...
    task.cancel()
    # Not awaiting the task - BAD!
  
    # Application continues...
```

If you cancel a task but never await it, you won't catch any exceptions that occurred during its execution, and you won't know when it actually completes. Always await a task after cancelling it.

### 3. Not Handling Cancellation in Resource Cleanup

```python
async def with_resource():
    resource = await acquire_resource()
    try:
        await use_resource(resource)
    finally:
        # This could be skipped if cancelled between try and finally
        await release_resource(resource)
```

The proper pattern is:

```python
async def with_resource():
    resource = await acquire_resource()
    try:
        await use_resource(resource)
    finally:
        try:
            await release_resource(resource)
        except asyncio.CancelledError:
            # Make sure cleanup happens even during cancellation
            await release_resource(resource)
            raise
```

## Structured Concurrency

Python 3.11+ promotes the concept of structured concurrency with TaskGroup, which helps manage task lifetimes:

```python
async def main():
    async with asyncio.TaskGroup() as tg:
        task1 = tg.create_task(work1())
        task2 = tg.create_task(work2())
        # If any task fails, all other tasks are cancelled
        # When we exit the context, all tasks must be complete
```

Structured concurrency provides important guarantees:

1. All tasks created in a scope are completed when that scope exits
2. Exceptions in any task propagate to the parent scope
3. Cancellation of the parent scope cancels all child tasks

This approach helps prevent many common bugs with task management and cancellation by making task relationships explicit.

## Conclusion

Task management and cancellation in asyncio form the foundation of robust asynchronous Python code. From our exploration, we've learned:

1. Tasks are wrappers around coroutines that allow them to be scheduled, monitored, and managed
2. Cancellation is cooperative and only happens at await points
3. Proper handling of cancellation is crucial for resource cleanup and graceful shutdown
4. Newer features like TaskGroup provide structured approaches to manage task lifetimes

When working with asyncio, always think about:

* How tasks relate to each other
* How cancellation will propagate through your system
* Where resources need cleanup, even during cancellation
* How to structure your code to make task lifetimes clear

With these principles in mind, you can build robust, concurrent applications that gracefully handle cancellation and manage resources properly.
