
## What is Middleware in Express.js?

Before we dive into error handling, let's understand what middleware actually is from first principles.

Think of middleware as a series of checkpoints or filters that every request passes through before reaching its final destination. It's like airport security - passengers (requests) go through multiple checkpoints (middleware) before boarding their flight (reaching the route handler).

```javascript
// Basic middleware example
const express = require('express');
const app = express();

// This is a middleware function
app.use((req, res, next) => {
    console.log('Request received at:', new Date().toISOString());
    // Pass control to the next middleware
    next();
});

app.get('/', (req, res) => {
    res.send('Hello World!');
});
```

> **Key Concept** : The `next()` function is crucial - it passes control to the next middleware in the chain. Without calling `next()`, the request will hang forever!

## Understanding Asynchronous Operations

Now let's understand what makes operations "async" in Node.js:

```javascript
// Synchronous operation - blocks execution
const data = fs.readFileSync('file.txt', 'utf8');
console.log(data);
console.log('This runs after file is read');

// Asynchronous operation - non-blocking
fs.readFile('file.txt', 'utf8', (err, data) => {
    if (err) {
        console.error('Error:', err);
        return;
    }
    console.log(data);
});
console.log('This runs immediately, before file is read');
```

> **Important** : Asynchronous operations don't block the event loop, allowing Node.js to handle multiple requests simultaneously.

## Basic Error Handling in Express

Express has built-in error handling middleware that catches synchronous errors automatically:

```javascript
app.get('/error', (req, res) => {
    // This error will be caught by Express
    throw new Error('Something went wrong!');
});

// Error handling middleware (must be last)
app.use((err, req, res, next) => {
    console.error(err.stack);
    res.status(500).send('Something broke!');
});
```

## The Challenge with Async Errors

Here's where it gets tricky. Express doesn't automatically catch errors from asynchronous operations:

```javascript
// This error will NOT be caught by Express
app.get('/async-error', (req, res) => {
    setTimeout(() => {
        throw new Error('Async error!'); // This crashes the server!
    }, 1000);
});

// This promise rejection is also not caught
app.get('/promise-error', (req, res) => {
    const promise = new Promise((resolve, reject) => {
        setTimeout(() => {
            reject(new Error('Promise rejected!'));
        }, 1000);
    });
  
    promise.catch(err => {
        // Even this doesn't help - Express doesn't know about this error
        throw err;
    });
});
```

> **Critical Understanding** : Express error handling only works with synchronous code or properly forwarded async errors.

## Solution 1: Using Callbacks with Error-First Pattern

The classic Node.js pattern for handling async errors:

```javascript
app.get('/user/:id', (req, res, next) => {
    // Async operation with callback
    User.findById(req.params.id, (err, user) => {
        if (err) {
            // Forward error to Express error handler
            return next(err);
        }
      
        if (!user) {
            // Create custom error
            const notFoundError = new Error('User not found');
            notFoundError.status = 404;
            return next(notFoundError);
        }
      
        res.json(user);
    });
});
```

## Solution 2: Promise-Based Approach with Catch

Modern Express middleware using promises:

```javascript
// Middleware that returns a promise
app.get('/posts', (req, res, next) => {
    Post.find()
        .then(posts => {
            res.json(posts);
        })
        .catch(err => {
            // Forward error to Express
            next(err);
        });
});

// Cleaner version with async/await
app.get('/posts-async', async (req, res, next) => {
    try {
        const posts = await Post.find();
        res.json(posts);
    } catch (err) {
        // Forward error to Express
        next(err);
    }
});
```

## Solution 3: Creating an Async Error Wrapper

Let's create a reusable wrapper to handle async errors automatically:

```javascript
// Utility function to wrap async middleware
const asyncHandler = (fn) => {
    return (req, res, next) => {
        // Convert function result to promise and catch errors
        Promise.resolve(fn(req, res, next)).catch(next);
    };
};

// Usage example
app.get('/products', asyncHandler(async (req, res) => {
    // Any error thrown here will be caught automatically
    const products = await Product.find();
  
    if (!products.length) {
        throw new Error('No products found');
    }
  
    res.json(products);
}));
```

Let me break down how this wrapper works:

1. `asyncHandler` takes an async function as input
2. It returns a new function that Express can use as middleware
3. Inside, we convert the function to a promise and catch any errors
4. If an error occurs, it's passed to `next()`, which forwards it to Express

## Advanced Error Handling Patterns

### Custom Error Classes

Creating structured error responses:

```javascript
// Custom error class
class AppError extends Error {
    constructor(message, statusCode) {
        super(message);
        this.statusCode = statusCode;
        this.status = `${statusCode}`.startsWith('4') ? 'fail' : 'error';
        this.isOperational = true;
      
        Error.captureStackTrace(this, this.constructor);
    }
}

// Usage in middleware
app.get('/order/:id', asyncHandler(async (req, res) => {
    const order = await Order.findById(req.params.id);
  
    if (!order) {
        throw new AppError('Order not found', 404);
    }
  
    if (!order.isPaid) {
        throw new AppError('Payment required', 402);
    }
  
    res.json(order);
}));
```

### Global Error Handler with Different Environments

```javascript
// Error handler middleware
const errorHandler = (err, req, res, next) => {
    // Log error for debugging
    console.error('Error 💥', err);
  
    // Send appropriate response based on environment
    if (process.env.NODE_ENV === 'development') {
        // Detailed error in development
        res.status(err.statusCode || 500).json({
            status: err.status || 'error',
            error: err,
            message: err.message,
            stack: err.stack
        });
    } else {
        // Clean error message in production
        if (err.isOperational) {
            res.status(err.statusCode).json({
                status: err.status,
                message: err.message
            });
        } else {
            // Unexpected errors
            res.status(500).json({
                status: 'error',
                message: 'Something went wrong!'
            });
        }
    }
};

// Apply error handler
app.use(errorHandler);
```

## Complete Real-World Example

Let's put it all together in a realistic scenario:

```javascript
const express = require('express');
const app = express();

// Async wrapper
const asyncHandler = (fn) => {
    return (req, res, next) => {
        Promise.resolve(fn(req, res, next)).catch(next);
    };
};

// Custom error class
class AppError extends Error {
    constructor(message, statusCode) {
        super(message);
        this.statusCode = statusCode;
        this.status = `${statusCode}`.startsWith('4') ? 'fail' : 'error';
        this.isOperational = true;
    }
}

// Validation middleware
const validateUser = asyncHandler(async (req, res, next) => {
    const { email, password } = req.body;
  
    if (!email || !password) {
        throw new AppError('Email and password required', 400);
    }
  
    // Simulate database check
    const userExists = await User.findOne({ email });
  
    if (userExists) {
        throw new AppError('Email already registered', 409);
    }
  
    next();
});

// Route with multiple async middleware
app.post('/register', 
    validateUser,
    asyncHandler(async (req, res) => {
        // Hash password
        const hashedPassword = await bcrypt.hash(req.body.password, 12);
      
        // Create user
        const user = await User.create({
            email: req.body.email,
            password: hashedPassword
        });
      
        // Send email (async operation)
        await sendWelcomeEmail(user.email);
      
        res.status(201).json({
            status: 'success',
            data: { user }
        });
    })
);

// Global error handler
app.use((err, req, res, next) => {
    console.error('Error:', err);
  
    const { statusCode = 500, message } = err;
  
    res.status(statusCode).json({
        status: err.status || 'error',
        message: message
    });
});
```

## Mobile-Optimized Error Flow Diagram

```
┌─────────────────────┐
│   Client Request    │
└─────────────────────┘
          │
          ▼
┌─────────────────────┐
│   Middleware 1      │ ◄─── Async operation
└─────────────────────┘      might throw error
          │
          ▼
┌─────────────────────┐
│   Middleware 2      │ ◄─── Validation error
└─────────────────────┘      might throw
          │
          ▼
┌─────────────────────┐
│   Route Handler     │ ◄─── Database error
└─────────────────────┘      might throw
          │
          │ (error occurs)
          ▼
┌─────────────────────┐
│   next(error)       │ ─┐
└─────────────────────┘  │
          │              │
          ▼              │
┌─────────────────────┐  │
│  Error Middleware   │ ◄┘
└─────────────────────┘
          │
          ▼
┌─────────────────────┐
│  Error Response     │
└─────────────────────┘
```

> **Best Practice** : Always use `asyncHandler` or try-catch blocks with async/await to ensure errors are properly forwarded to Express error handling middleware.

## Common Pitfalls and Solutions

### Pitfall 1: Forgetting to call next()

```javascript
// ❌ Wrong - error is not forwarded
app.get('/data', async (req, res) => {
    try {
        const data = await fetchData();
        res.json(data);
    } catch (err) {
        console.error(err); // Only logs, doesn't handle
    }
});

// ✅ Correct - error is forwarded
app.get('/data', async (req, res, next) => {
    try {
        const data = await fetchData();
        res.json(data);
    } catch (err) {
        next(err); // Forwards to error middleware
    }
});
```

### Pitfall 2: Mixing callback and promise patterns

```javascript
// ❌ Confusing - mixed patterns
app.get('/mixed', (req, res, next) => {
    User.findById(req.params.id, async (err, user) => {
        if (err) return next(err);
      
        try {
            await user.updateActivity();
            res.json(user);
        } catch (err) {
            next(err);
        }
    });
});

// ✅ Clean - consistent async/await
app.get('/clean', asyncHandler(async (req, res) => {
    const user = await User.findById(req.params.id);
    await user.updateActivity();
    res.json(user);
}));
```

## Summary

Async middleware error handling in Express requires understanding these key concepts:

1. Express only catches synchronous errors automatically
2. Async errors must be explicitly forwarded using `next(error)`
3. Using utility functions like `asyncHandler` simplifies error handling
4. Custom error classes improve error management
5. Global error middleware provides consistent error responses

By following these patterns, you can create robust Express applications that handle errors gracefully, providing better user experience and easier debugging.
