# Understanding Timeouts and Cancellation in Python Asyncio: From First Principles

Let me take you on a journey through one of the most crucial aspects of asynchronous programming: timeouts and cancellation. We'll start from the very foundation and build up to mastering these concepts in Python's asyncio.

## What Are Timeouts and Cancellation? The Fundamental Concepts

Before diving into asyncio specifics, let's understand what these concepts mean in the real world.

> **Timeout** : A predetermined limit on how long you're willing to wait for something to complete. Think of it like setting a timer when you're waiting for a friend - if they don't show up within 30 minutes, you leave.

> **Cancellation** : The ability to stop an ongoing operation before it naturally completes. It's like deciding to stop waiting for that friend and leaving early, even if the 30-minute timer hasn't gone off yet.

These concepts become critically important in asynchronous programming because you're often dealing with operations that might take unpredictable amounts of time - network requests, file operations, database queries, or user interactions.

## Why Do We Need Timeouts and Cancellation in Async Programming?

Imagine you're building a web application that fetches data from multiple external APIs. Without timeouts and cancellation, several problems could occur:

 **The Hanging Operation Problem** : One slow API could make your entire application unresponsive. Users would wait indefinitely for a page to load.

 **Resource Exhaustion** : Without limits, you might accumulate thousands of pending operations, consuming memory and system resources.

 **User Experience Degradation** : Users expect responsive applications. They'd rather see an error message after 5 seconds than wait 2 minutes for a response.

 **Cascading Failures** : In complex systems, one slow component can cause backups throughout the entire system.

## The Foundation: Understanding Asyncio Tasks and Coroutines

Before we explore timeouts and cancellation, we need to understand what we're timing out and cancelling. In asyncio, we primarily work with:

 **Coroutines** : Functions defined with `async def` that can be paused and resumed.
 **Tasks** : Wrapped coroutines that asyncio can manage and schedule.

Here's a simple example to establish our foundation:

```python
import asyncio
import time

async def slow_operation(name, duration):
    """A simple coroutine that simulates work by sleeping"""
    print(f"Starting {name} - will take {duration} seconds")
    await asyncio.sleep(duration)  # Simulates async work
    print(f"Completed {name}")
    return f"Result from {name}"

async def main():
    # Create a task from our coroutine
    task = asyncio.create_task(slow_operation("API call", 3))
  
    # Wait for the task to complete
    result = await task
    print(f"Got: {result}")

# Run the example
asyncio.run(main())
```

In this example, `slow_operation` is a coroutine that simulates an operation taking 3 seconds. The `asyncio.create_task()` function wraps our coroutine into a Task object that asyncio can manage. The task runs concurrently with other operations, but since we're only running one thing here, it simply completes after 3 seconds.

## Introducing Timeouts: The `asyncio.wait_for()` Function

The most straightforward way to add timeouts to asyncio operations is using `asyncio.wait_for()`. This function allows you to specify a maximum time to wait for a coroutine to complete.

```python
import asyncio

async def potentially_slow_operation():
    """This operation might take a long time"""
    print("Starting potentially slow operation...")
    await asyncio.sleep(5)  # Simulates 5 seconds of work
    print("Operation completed!")
    return "Success!"

async def main_with_timeout():
    try:
        # Set a timeout of 3 seconds for our operation
        result = await asyncio.wait_for(
            potentially_slow_operation(), 
            timeout=3.0
        )
        print(f"Result: {result}")
  
    except asyncio.TimeoutError:
        print("Operation timed out after 3 seconds!")

# Run the example
asyncio.run(main_with_timeout())
```

Let's break down what happens here:

1. **Timeout Setting** : `asyncio.wait_for()` wraps our coroutine and sets a 3-second limit
2. **Execution Monitoring** : asyncio starts executing `potentially_slow_operation()`
3. **Timeout Enforcement** : After 3 seconds, since the operation hasn't completed (it needs 5 seconds), asyncio raises a `TimeoutError`
4. **Exception Handling** : We catch the `TimeoutError` and handle it gracefully

> **Key Insight** : When a timeout occurs, the underlying operation doesn't just stop - it gets cancelled. This is where timeouts and cancellation intersect.

## Understanding Cancellation: The Cooperative Nature

Cancellation in asyncio is  **cooperative** , which means that a coroutine must explicitly check if it has been cancelled and respond appropriately. This is different from forceful termination that you might see in threading.

Let's see how cancellation works at a basic level:

```python
import asyncio

async def cancellable_operation():
    """An operation that can be cancelled cooperatively"""
    try:
        for i in range(10):
            print(f"Working... step {i + 1}/10")
            await asyncio.sleep(1)  # This is a cancellation point
        return "Completed all work!"
  
    except asyncio.CancelledError:
        print("Operation was cancelled!")
        # You can do cleanup here if needed
        raise  # Re-raise to properly propagate the cancellation

async def main_with_cancellation():
    # Create a task
    task = asyncio.create_task(cancellable_operation())
  
    # Let it run for 3 seconds, then cancel it
    await asyncio.sleep(3)
    task.cancel()
  
    try:
        result = await task
        print(f"Result: {result}")
    except asyncio.CancelledError:
        print("Task was successfully cancelled")

# Run the example
asyncio.run(main_with_cancellation())
```

Here's what's happening step by step:

1. **Task Creation** : We create a task that will run for 10 seconds (10 sleep cycles)
2. **Cancellation Request** : After 3 seconds, we call `task.cancel()`
3. **Cancellation Point** : The next time the task hits `await asyncio.sleep(1)`, it checks for cancellation
4. **Exception Raising** : Since cancellation was requested, `asyncio.CancelledError` is raised
5. **Exception Handling** : We catch and handle the cancellation appropriately

> **Critical Concept** : Cancellation only occurs at "await points" - places where the coroutine yields control back to the event loop. If you have a long-running synchronous operation (like a complex calculation), it won't be cancellable until it hits an await.

## Timeout vs. Cancellation: Understanding the Relationship

When you use `asyncio.wait_for()` with a timeout, here's the complete picture of what happens internally:

```python
import asyncio

async def demonstrate_timeout_cancellation():
    """Shows how timeout leads to cancellation"""
  
    async def long_running_task():
        try:
            print("Task started")
            for i in range(10):
                print(f"Step {i + 1}: Still working...")
                await asyncio.sleep(1)
            return "Task completed normally"
      
        except asyncio.CancelledError:
            print("Task detected it was cancelled!")
            # Perform any necessary cleanup
            print("Cleanup completed")
            raise  # Important: re-raise the CancelledError
  
    try:
        # This will timeout after 4 seconds
        result = await asyncio.wait_for(long_running_task(), timeout=4.0)
        print(f"Result: {result}")
  
    except asyncio.TimeoutError:
        print("Timeout occurred - the task was automatically cancelled")

# Run the demonstration
asyncio.run(demonstrate_timeout_cancellation())
```

The flow here illustrates the timeout-cancellation relationship:

1. **Timeout Detection** : After 4 seconds, `wait_for()` detects the timeout
2. **Automatic Cancellation** : `wait_for()` automatically cancels the underlying task
3. **Cancellation Propagation** : The task receives `CancelledError` at its next await point
4. **Exception Translation** : `wait_for()` catches the `CancelledError` and raises `TimeoutError` instead

## Advanced Timeout Patterns: Multiple Operations

Real applications often need to handle timeouts for multiple concurrent operations. Let's explore several patterns:

### Pattern 1: Timeout for All Operations

```python
import asyncio

async def fetch_data(source, delay):
    """Simulates fetching data from different sources"""
    print(f"Fetching from {source}...")
    await asyncio.sleep(delay)
    return f"Data from {source}"

async def fetch_all_with_global_timeout():
    """Apply a single timeout to all operations combined"""
  
    async def fetch_multiple():
        # Start all operations concurrently
        tasks = [
            fetch_data("Database", 2),
            fetch_data("API", 3),
            fetch_data("Cache", 1)
        ]
      
        # Wait for all to complete
        results = await asyncio.gather(*tasks)
        return results
  
    try:
        # Give all operations a combined 5 seconds
        results = await asyncio.wait_for(fetch_multiple(), timeout=5.0)
        print(f"All results: {results}")
  
    except asyncio.TimeoutError:
        print("Not all operations completed within 5 seconds")

# Run the example
asyncio.run(fetch_all_with_global_timeout())
```

### Pattern 2: Individual Timeouts for Each Operation

```python
import asyncio

async def fetch_with_individual_timeouts():
    """Apply separate timeouts to each operation"""
  
    async def safe_fetch(source, delay, timeout):
        """Wrapper that applies timeout to individual operations"""
        try:
            return await asyncio.wait_for(
                fetch_data(source, delay), 
                timeout=timeout
            )
        except asyncio.TimeoutError:
            return f"Timeout: {source} took too long"
  
    # Start all operations with different timeout limits
    tasks = [
        safe_fetch("Database", 2, 3.0),  # 3 second timeout
        safe_fetch("API", 4, 2.0),       # 2 second timeout (will timeout)
        safe_fetch("Cache", 1, 5.0)      # 5 second timeout
    ]
  
    # Wait for all operations (successful or timed out)
    results = await asyncio.gather(*tasks)
  
    for result in results:
        print(result)

# Run the example
asyncio.run(fetch_with_individual_timeouts())
```

## Using `asyncio.wait()` for Fine-Grained Control

For more sophisticated timeout handling, `asyncio.wait()` provides fine-grained control over multiple concurrent operations:

```python
import asyncio

async def demonstrate_asyncio_wait():
    """Shows advanced timeout control with asyncio.wait()"""
  
    async def task_with_id(task_id, duration):
        """A task that identifies itself"""
        try:
            await asyncio.sleep(duration)
            return f"Task {task_id} completed"
        except asyncio.CancelledError:
            return f"Task {task_id} was cancelled"
  
    # Create multiple tasks with different durations
    tasks = [
        asyncio.create_task(task_with_id(1, 1)),
        asyncio.create_task(task_with_id(2, 3)),
        asyncio.create_task(task_with_id(3, 5)),
        asyncio.create_task(task_with_id(4, 2))
    ]
  
    try:
        # Wait for tasks with a 2.5 second timeout
        done, pending = await asyncio.wait(
            tasks, 
            timeout=2.5,
            return_when=asyncio.FIRST_EXCEPTION  # Stop on first exception
        )
      
        print(f"Completed tasks: {len(done)}")
        print(f"Pending tasks: {len(pending)}")
      
        # Process completed tasks
        for task in done:
            result = await task
            print(f"Result: {result}")
      
        # Cancel remaining tasks
        for task in pending:
            task.cancel()
            print(f"Cancelled task: {task}")
      
        # Wait for cancellations to complete
        if pending:
            await asyncio.gather(*pending, return_exceptions=True)
  
    except Exception as e:
        print(f"Exception occurred: {e}")

# Run the demonstration
asyncio.run(demonstrate_asyncio_wait())
```

This example demonstrates several important concepts:

 **Task Management** : We create multiple tasks and manage them as a group
 **Partial Completion** : Some tasks complete within the timeout, others don't
 **Cleanup** : We explicitly cancel pending tasks to prevent resource leaks
 **Exception Handling** : We use `return_exceptions=True` to handle cancellation exceptions gracefully

## Context Managers and Automatic Timeout Management

For more elegant timeout management, you can create context managers that automatically handle timeouts:

```python
import asyncio
from contextlib import asynccontextmanager

@asynccontextmanager
async def timeout_context(seconds):
    """A context manager that provides automatic timeout handling"""
    task = asyncio.current_task()
  
    # Create a timeout task
    timeout_task = asyncio.create_task(asyncio.sleep(seconds))
  
    try:
        yield timeout_task
    finally:
        # Clean up the timeout task
        if not timeout_task.done():
            timeout_task.cancel()
            try:
                await timeout_task
            except asyncio.CancelledError:
                pass

async def operation_with_context_timeout():
    """Shows how to use a timeout context manager"""
  
    async def some_operation():
        print("Starting operation...")
        await asyncio.sleep(3)
        print("Operation completed!")
        return "Success"
  
    try:
        async with timeout_context(2.0) as timeout_task:
            # Race between our operation and the timeout
            operation_task = asyncio.create_task(some_operation())
          
            done, pending = await asyncio.wait(
                [operation_task, timeout_task],
                return_when=asyncio.FIRST_COMPLETED
            )
          
            if timeout_task in done:
                operation_task.cancel()
                await asyncio.gather(operation_task, return_exceptions=True)
                raise asyncio.TimeoutError("Operation timed out")
            else:
                result = await operation_task
                return result
  
    except asyncio.TimeoutError:
        print("Operation was cancelled due to timeout")
        return None

# Run the example
result = asyncio.run(operation_with_context_timeout())
print(f"Final result: {result}")
```

## Handling Cancellation Gracefully: Best Practices

When writing cancellable operations, following these patterns ensures robust behavior:

```python
import asyncio
import logging

# Set up logging to see what's happening
logging.basicConfig(level=logging.INFO)
logger = logging.getLogger(__name__)

async def robust_operation_with_cleanup():
    """Demonstrates proper cancellation handling with resource cleanup"""
  
    # Simulate acquiring a resource
    resource_acquired = False
  
    try:
        logger.info("Acquiring resource...")
        await asyncio.sleep(0.5)  # Simulate resource acquisition
        resource_acquired = True
        logger.info("Resource acquired successfully")
      
        # Main operation work
        for i in range(10):
            logger.info(f"Processing step {i + 1}/10")
            await asyncio.sleep(1)  # Cancellation point
      
        logger.info("Operation completed successfully")
        return "Operation successful"
  
    except asyncio.CancelledError:
        logger.info("Operation cancelled - performing cleanup")
      
        # Critical: Perform cleanup even when cancelled
        if resource_acquired:
            logger.info("Releasing resource...")
            await asyncio.sleep(0.1)  # Simulate cleanup work
            logger.info("Resource released")
      
        # Re-raise the cancellation to properly propagate it
        raise
  
    finally:
        logger.info("Finally block executed")

async def main_with_proper_cancellation():
    """Shows proper cancellation handling"""
  
    task = asyncio.create_task(robust_operation_with_cleanup())
  
    # Let it run for 3 seconds, then cancel
    await asyncio.sleep(3)
    logger.info("Requesting cancellation...")
    task.cancel()
  
    try:
        result = await task
        logger.info(f"Result: {result}")
    except asyncio.CancelledError:
        logger.info("Task was properly cancelled")

# Run the example
asyncio.run(main_with_proper_cancellation())
```

> **Essential Practice** : Always re-raise `CancelledError` after performing cleanup. This ensures that cancellation properly propagates through the call stack.

## Common Pitfalls and How to Avoid Them

Let me show you some common mistakes and their solutions:

### Pitfall 1: Swallowing Cancellation Exceptions

```python
import asyncio

# ❌ WRONG: This swallows cancellation
async def bad_exception_handling():
    try:
        await asyncio.sleep(10)
    except Exception:  # This catches CancelledError too!
        print("Something went wrong")
        return "Error result"

# ✅ CORRECT: Properly handle cancellation
async def good_exception_handling():
    try:
        await asyncio.sleep(10)
    except asyncio.CancelledError:
        print("Operation was cancelled")
        raise  # Re-raise cancellation
    except Exception as e:
        print(f"Other error occurred: {e}")
        return "Error result"
```

### Pitfall 2: Not Handling Cancellation in Loops

```python
import asyncio

# ❌ WRONG: Long-running loop without cancellation points
async def bad_loop():
    for i in range(1000000):
        # Heavy computation with no await - not cancellable!
        result = sum(range(1000))
    return result

# ✅ CORRECT: Add periodic cancellation checks
async def good_loop():
    for i in range(1000000):
        # Heavy computation
        result = sum(range(1000))
      
        # Periodic cancellation check
        if i % 1000 == 0:
            await asyncio.sleep(0)  # Yield control to event loop
    return result
```

### Pitfall 3: Incorrect Timeout Scope

```python
import asyncio

# ❌ WRONG: Timeout applied to wrong scope
async def bad_timeout_scope():
    try:
        # Timeout applies to entire function, including setup
        result = await asyncio.wait_for(
            expensive_setup_and_operation(),
            timeout=5.0
        )
    except asyncio.TimeoutError:
        print("Timeout - but was it setup or operation?")

async def expensive_setup_and_operation():
    await asyncio.sleep(3)  # Setup
    await asyncio.sleep(4)  # Operation - this will timeout
    return "Done"

# ✅ CORRECT: Separate timeouts for different phases
async def good_timeout_scope():
    try:
        # Setup with its own timeout
        await asyncio.wait_for(setup_phase(), timeout=5.0)
      
        # Operation with different timeout
        result = await asyncio.wait_for(operation_phase(), timeout=3.0)
        return result
      
    except asyncio.TimeoutError as e:
        print("Timeout occurred in specific phase")
        raise

async def setup_phase():
    await asyncio.sleep(3)
    print("Setup complete")

async def operation_phase():
    await asyncio.sleep(2)
    return "Operation complete"
```

## Real-World Example: HTTP Client with Timeouts

Let's put everything together in a practical example that demonstrates proper timeout and cancellation handling in an HTTP client scenario:

```python
import asyncio
import aiohttp
from typing import Optional, Dict, Any

class TimeoutHTTPClient:
    """HTTP client with comprehensive timeout handling"""
  
    def __init__(self, default_timeout: float = 30.0):
        self.default_timeout = default_timeout
        self.session: Optional[aiohttp.ClientSession] = None
  
    async def __aenter__(self):
        """Context manager entry"""
        self.session = aiohttp.ClientSession()
        return self
  
    async def __aexit__(self, exc_type, exc_val, exc_tb):
        """Context manager exit with cleanup"""
        if self.session:
            await self.session.close()
  
    async def fetch_with_timeout(
        self, 
        url: str, 
        timeout: Optional[float] = None,
        retries: int = 2
    ) -> Dict[str, Any]:
        """
        Fetch URL with timeout and retry logic
      
        Args:
            url: URL to fetch
            timeout: Request timeout (uses default if None)
            retries: Number of retry attempts
      
        Returns:
            Dictionary with response data and metadata
        """
        timeout = timeout or self.default_timeout
        last_exception = None
      
        for attempt in range(retries + 1):
            try:
                print(f"Attempt {attempt + 1}/{retries + 1} for {url}")
              
                async with asyncio.timeout(timeout):  # Python 3.11+ syntax
                    async with self.session.get(url) as response:
                        content = await response.text()
                      
                        return {
                            'url': url,
                            'status': response.status,
                            'content': content[:100] + '...' if len(content) > 100 else content,
                            'attempt': attempt + 1,
                            'success': True
                        }
          
            except asyncio.TimeoutError:
                last_exception = f"Timeout after {timeout} seconds"
                print(f"Timeout on attempt {attempt + 1}")
              
            except aiohttp.ClientError as e:
                last_exception = f"Client error: {e}"
                print(f"Client error on attempt {attempt + 1}: {e}")
          
            except asyncio.CancelledError:
                print("Request was cancelled")
                raise  # Don't retry on cancellation
          
            # Wait before retry (with exponential backoff)
            if attempt < retries:
                wait_time = 2 ** attempt
                print(f"Waiting {wait_time} seconds before retry...")
                await asyncio.sleep(wait_time)
      
        # All attempts failed
        return {
            'url': url,
            'success': False,
            'error': last_exception,
            'attempts': retries + 1
        }

# Example usage
async def demonstrate_http_client():
    """Demonstrate the HTTP client with various scenarios"""
  
    urls = [
        "https://httpbin.org/delay/1",  # Fast response
        "https://httpbin.org/delay/5",  # Slow response
        "https://nonexistent-domain-12345.com",  # Will fail
    ]
  
    async with TimeoutHTTPClient(default_timeout=3.0) as client:
        tasks = []
      
        for url in urls:
            task = asyncio.create_task(
                client.fetch_with_timeout(url, timeout=2.0)
            )
            tasks.append(task)
      
        # Wait for all requests with overall timeout
        try:
            results = await asyncio.wait_for(
                asyncio.gather(*tasks, return_exceptions=True),
                timeout=10.0
            )
          
            for result in results:
                if isinstance(result, Exception):
                    print(f"Exception: {result}")
                else:
                    print(f"Result: {result}")
      
        except asyncio.TimeoutError:
            print("Overall operation timed out")
            # Cancel any remaining tasks
            for task in tasks:
                if not task.done():
                    task.cancel()

# Note: This example requires aiohttp
# Install with: pip install aiohttp
# asyncio.run(demonstrate_http_client())
```

## Summary: Key Principles for Timeouts and Cancellation

As we conclude this deep dive, let's crystallize the essential principles:

> **Principle 1: Cooperative Design** - Cancellation in asyncio is cooperative. Your coroutines must actively participate by having regular await points and properly handling `CancelledError`.

> **Principle 2: Timeout Granularity** - Apply timeouts at the appropriate level. Sometimes you want individual operation timeouts, sometimes overall timeouts, and often both.

> **Principle 3: Resource Cleanup** - Always perform necessary cleanup in cancellation handlers, but don't forget to re-raise the `CancelledError` to maintain proper cancellation propagation.

> **Principle 4: Exception Hierarchy** - Be specific about which exceptions you catch. Don't accidentally swallow `CancelledError` with broad exception handlers.

> **Principle 5: Graceful Degradation** - Design your applications to handle timeouts and cancellations gracefully, providing meaningful feedback to users and maintaining system stability.

Understanding these concepts deeply will make you a more effective asyncio programmer, capable of building robust, responsive applications that handle the unpredictable nature of asynchronous operations with confidence and grace.
