# Go's Defer, Panic, and Recover Mechanisms: From First Principles

Go's error handling philosophy revolves around explicit error checking, but it also provides powerful mechanisms for deferred execution and handling unexpected errors. Let's explore defer, panic, and recover from first principles, building our understanding systematically.

## Defer: Function Call Scheduling

### What is Defer?

At its most fundamental level, `defer` is a mechanism to schedule function calls to be executed when the surrounding function returns. It's a way to ensure that certain operations happen, regardless of which path the execution takes through a function.

Think of `defer` as leaving a note to your future self saying, "Don't forget to do this before you leave the room."

### How Defer Works: The Execution Model

When the Go compiler encounters a `defer` statement:

1. It evaluates the arguments to the deferred function call immediately
2. It pushes the function and its pre-evaluated arguments onto a stack
3. When the surrounding function returns (for any reason), it executes all deferred functions in last-in-first-out (LIFO) order

### A Simple Defer Example

Let's start with a basic example:

```go
package main

import "fmt"

func main() {
    fmt.Println("Start")
    defer fmt.Println("This runs later")
    fmt.Println("End")
}
```

Output:

```
Start
End
This runs later
```

Notice how the deferred statement executes after "End", even though it appears before "End" in the code. This is because `defer` postpones the execution until the function returns.

### Multiple Defers: The Stack Model

Deferred functions follow a stack model - Last In, First Out (LIFO):

```go
package main

import "fmt"

func main() {
    fmt.Println("Counting:")
  
    for i := 0; i < 3; i++ {
        defer fmt.Println(i)
    }
  
    fmt.Println("Done counting")
}
```

Output:

```
Counting:
Done counting
2
1
0
```

This demonstrates how deferred functions are executed in reverse order. Think of it like stacking plates - the last one placed on top is the first one removed.

### Argument Evaluation: A Common Confusion Point

One crucial detail is when the arguments to a deferred function are evaluated:

```go
package main

import "fmt"

func main() {
    x := 1
    defer fmt.Println("Value of x:", x)
    x = 2
    fmt.Println("x has been changed to:", x)
}
```

Output:

```
x has been changed to: 2
Value of x: 1
```

Notice that the deferred function prints `1`, not `2`. This is because the arguments to `fmt.Println` are evaluated when the `defer` statement is encountered, not when the function is actually executed.

### Practical Usage: Resource Management

The most common use case for `defer` is resource cleanup. Here's a classic file handling example:

```go
package main

import (
    "fmt"
    "os"
)

func readFile(filename string) error {
    file, err := os.Open(filename)
    if err != nil {
        return err
    }
    defer file.Close() // This ensures the file is closed when the function exits
  
    // Read file contents
    buffer := make([]byte, 100)
    _, err = file.Read(buffer)
    if err != nil {
        return err // Even if we return here, file.Close() still executes
    }
  
    fmt.Println("File contents:", string(buffer))
    return nil // file.Close() executes here too
}

func main() {
    err := readFile("example.txt")
    if err != nil {
        fmt.Println("Error:", err)
    }
}
```

This pattern ensures resources are always properly released, regardless of how the function exits.

### Deferred Anonymous Functions: Capturing the Environment

Deferred functions can be anonymous functions that capture values from their environment:

```go
package main

import "fmt"

func main() {
    x := 1
  
    defer func() {
        fmt.Println("x in deferred func:", x)
    }()
  
    x = 2
    fmt.Println("x in main:", x)
}
```

Output:

```
x in main: 2
x in deferred func: 2
```

Unlike the previous example where the argument was evaluated immediately, here the anonymous function captures a reference to `x`, so it sees the updated value.

## Panic: When Things Go Wrong

### What is Panic?

A panic is Go's mechanism for handling exceptional errors that shouldn't occur during normal operation. When a function panics, normal execution stops, any deferred functions are executed, and control returns to the calling function.

Think of panic as pulling the emergency brake on a train.

### When Panics Occur

Panics can occur in two ways:

1. Automatically by the runtime (e.g., array index out of bounds, nil pointer dereference)
2. Explicitly by calling the `panic()` function

### The Anatomy of a Panic

Let's look at a simple explicit panic:

```go
package main

import "fmt"

func main() {
    fmt.Println("Starting the program")
    panic("something went terribly wrong")
    fmt.Println("This line will never be executed")
}
```

Output:

```
Starting the program
panic: something went terribly wrong

goroutine 1 [running]:
main.main()
        /tmp/sandbox.go:7 +0x39
exit status 2
```

The program prints the initial message, then encounters the panic, prints the panic message with a stack trace, and terminates without executing the final print statement.

### Defer and Panic Interaction

Deferred functions still execute during a panic:

```go
package main

import "fmt"

func main() {
    defer fmt.Println("This will still execute")
    fmt.Println("Starting the program")
    panic("something went wrong")
    fmt.Println("This line will never execute")
}
```

Output:

```
Starting the program
This will still execute
panic: something went wrong

goroutine 1 [running]:
main.main()
        /tmp/sandbox.go:8 +0xb9
exit status 2
```

Notice that the deferred statement executed before the program terminated due to the panic.

### Panic Propagation

Panics propagate up the call stack:

```go
package main

import "fmt"

func level3() {
    fmt.Println("In level3")
    panic("panic in level3")
    fmt.Println("This won't print")
}

func level2() {
    fmt.Println("In level2")
    defer fmt.Println("Deferred in level2")
    level3()
    fmt.Println("This won't print")
}

func level1() {
    fmt.Println("In level1")
    defer fmt.Println("Deferred in level1")
    level2()
    fmt.Println("This won't print")
}

func main() {
    fmt.Println("In main")
    defer fmt.Println("Deferred in main")
    level1()
    fmt.Println("This won't print")
}
```

Output:

```
In main
In level1
In level2
In level3
Deferred in level2
Deferred in level1
Deferred in main
panic: panic in level3

goroutine 1 [running]:
main.level3()
        /tmp/sandbox.go:7 +0x39
main.level2()
        /tmp/sandbox.go:13 +0xb9
main.level1()
        /tmp/sandbox.go:20 +0xb9
main.main()
        /tmp/sandbox.go:27 +0xb9
exit status 2
```

This demonstrates how a panic in `level3` unwinds the stack, executing deferred functions in each function as it goes.

## Recover: Catching the Panic

### What is Recover?

`recover` is a built-in function that regains control of a panicking goroutine. It's only useful inside deferred functions. During normal execution, `recover` returns `nil`. If called during a panic, `recover` captures the panic value and resumes normal execution.

Think of `recover` as a safety net catching a falling acrobat.

### Basic Recover Pattern

```go
package main

import "fmt"

func mayPanic() {
    panic("a problem occurred")
}

func main() {
    defer func() {
        if r := recover(); r != nil {
            fmt.Println("Recovered from panic:", r)
        }
    }()
  
    fmt.Println("Calling function that may panic")
    mayPanic()
    fmt.Println("This line will not run")
}
```

Output:

```
Calling function that may panic
Recovered from panic: a problem occurred
```

Notice that the program continues execution after recovering from the panic.

### Where to Place Recover

`recover` is only effective when it's called directly from a deferred function:

```go
package main

import "fmt"

func recoverExample() {
    // This will not work
    if r := recover(); r != nil {
        fmt.Println("This won't execute")
    }
}

func main() {
    defer recoverExample() // This won't catch the panic
  
    // This will work
    defer func() {
        if r := recover(); r != nil {
            fmt.Println("Panic recovered:", r)
        }
    }()
  
    panic("oh no")
}
```

Output:

```
Panic recovered: oh no
```

Only the second recover works because it's called directly inside a deferred function.

### Creating More Robust Functions with Recover

Recover allows you to create functions that can handle their own internal errors:

```go
package main

import "fmt"

func safeOperation(arg int) (result int, err error) {
    defer func() {
        if r := recover(); r != nil {
            err = fmt.Errorf("panic occurred: %v", r)
        }
    }()
  
    // Potentially panicking code
    if arg == 0 {
        panic("cannot process zero")
    }
  
    result = 10 / arg
    return result, nil
}

func main() {
    for _, val := range []int{5, 0, 2} {
        result, err := safeOperation(val)
        if err != nil {
            fmt.Println("Error:", err)
            continue
        }
        fmt.Println("Result:", result)
    }
  
    fmt.Println("Program completed successfully")
}
```

Output:

```
Result: 2
Error: panic occurred: cannot process zero
Result: 5
Program completed successfully
```

This pattern transforms panics into standard errors that can be handled normally.

## Putting It All Together: Practical Examples

### Example 1: Database Transaction Management

```go
package main

import (
    "database/sql"
    "fmt"
    _ "github.com/go-sql-driver/mysql"
)

func performTransaction(db *sql.DB) (err error) {
    // Start a transaction
    tx, err := db.Begin()
    if err != nil {
        return err
    }
  
    // Ensure the transaction is handled properly no matter what
    defer func() {
        if r := recover(); r != nil {
            // Something went horribly wrong, rollback
            tx.Rollback()
            err = fmt.Errorf("transaction panic: %v", r)
        } else if err != nil {
            // There was a regular error, rollback
            tx.Rollback()
        } else {
            // Everything went well, commit
            err = tx.Commit()
        }
    }()
  
    // Perform database operations that might panic
    _, err = tx.Exec("INSERT INTO users(name) VALUES (?)", "John")
    if err != nil {
        return err
    }
  
    // More operations...
  
    return nil
}
```

This example shows how defer, panic, and recover can work together to ensure database transactions are handled correctly, even if unexpected errors occur.

### Example 2: Web Server Error Handling

```go
package main

import (
    "fmt"
    "log"
    "net/http"
)

func safeHandler(fn http.HandlerFunc) http.HandlerFunc {
    return func(w http.ResponseWriter, r *http.Request) {
        defer func() {
            if err := recover(); err != nil {
                log.Printf("Panic: %v", err)
                http.Error(w, "Internal server error", http.StatusInternalServerError)
            }
        }()
        fn(w, r)
    }
}

func riskyHandler(w http.ResponseWriter, r *http.Request) {
    // Simulating something that might panic
    if r.URL.Path == "/panic" {
        panic("Something terrible happened!")
    }
    fmt.Fprintln(w, "Everything is fine")
}

func main() {
    http.HandleFunc("/", safeHandler(riskyHandler))
    log.Fatal(http.ListenAndServe(":8080", nil))
}
```

This demonstrates how to create a middleware that recovers from panics in HTTP handlers, preventing the entire server from crashing when a single request handler fails.

### Example 3: Resource Cleanup with Multiple Steps

```go
package main

import (
    "fmt"
    "os"
)

func processFiles() error {
    // Open first file
    file1, err := os.Open("file1.txt")
    if err != nil {
        return fmt.Errorf("failed to open file1: %w", err)
    }
    defer file1.Close() // Will be executed last
  
    // Open second file
    file2, err := os.Open("file2.txt")
    if err != nil {
        return fmt.Errorf("failed to open file2: %w", err)
    }
    defer file2.Close() // Will be executed second
  
    // Create output file
    output, err := os.Create("output.txt")
    if err != nil {
        return fmt.Errorf("failed to create output: %w", err)
    }
    defer output.Close() // Will be executed first
  
    // If something goes wrong here, all three files will still be closed
    // Process files...
  
    return nil
}
```

This example shows how defer statements stack, ensuring resources are released in the proper order (reverse of acquisition).

## Common Pitfalls and Best Practices

### Pitfall 1: Defer in Loops

Deferring function calls inside a loop can lead to unexpected resource usage:

```go
package main

import (
    "fmt"
    "os"
)

func badPractice() error {
    for i := 0; i < 10000; i++ {
        file, err := os.Open("large_file.txt")
        if err != nil {
            return err
        }
        defer file.Close() // This defers 10000 closes!
      
        // Do something with file
    }
    return nil // All 10000 deferred closes execute here
}

func goodPractice() error {
    for i := 0; i < 10000; i++ {
        if err := processFile("large_file.txt"); err != nil {
            return err
        }
    }
    return nil
}

func processFile(filename string) error {
    file, err := os.Open(filename)
    if err != nil {
        return err
    }
    defer file.Close() // Only one defer per loop iteration
  
    // Do something with file
    return nil
}
```

The bad practice defers 10,000 function calls that will only execute when the function returns. The good practice creates a separate function so each iteration gets its own defer stack.

### Pitfall 2: Modifying Return Values

Deferred anonymous functions can modify named return values:

```go
package main

import "fmt"

func example() (result int) {
    defer func() {
        result *= 2 // This modifies the return value
    }()
  
    return 5 // This sets result = 5, then the deferred function runs
}

func main() {
    fmt.Println(example()) // Prints 10, not 5
}
```

This can be powerful but also confusing if not used carefully.

### Pitfall 3: Recover Only Catches Local Panics

Recover only catches panics in the same goroutine:

```go
package main

import (
    "fmt"
    "time"
)

func main() {
    defer func() {
        if r := recover(); r != nil {
            fmt.Println("Recovered:", r)
        }
    }()
  
    go func() {
        panic("panic in goroutine") // This won't be caught by the recover in main
    }()
  
    time.Sleep(time.Second) // Give goroutine time to panic
    fmt.Println("Program still crashes")
}
```

Each goroutine needs its own recover mechanism.

### Best Practice 1: Keep Defer Simple

Deferred functions should be simple and focused primarily on cleanup:

```go
// Good: Simple defer focused on cleanup
defer file.Close()

// Bad: Complex logic in deferred function
defer func() {
    file.Close()
    data = processResults()
    updateDatabase(data)
    notifyUser()
}()
```

Complex logic is better placed in the main function body.

### Best Practice 2: Panic Only for Truly Exceptional Conditions

Use panic only for unrecoverable errors:

```go
// Bad: Using panic for expected errors
func readConfig(filename string) Config {
    data, err := os.ReadFile(filename)
    if err != nil {
        panic("Could not read config file") // Don't do this
    }
    // ...
}

// Good: Return errors for expected failure conditions
func readConfig(filename string) (Config, error) {
    data, err := os.ReadFile(filename)
    if err != nil {
        return Config{}, fmt.Errorf("reading config: %w", err)
    }
    // ...
}
```

### Best Practice 3: Convert Panics to Errors at API Boundaries

At package boundaries, convert panics to errors:

```go
package safemath

// ExportedFunction catches any panics and returns them as errors
func ExportedFunction(x, y int) (result int, err error) {
    defer func() {
        if r := recover(); r != nil {
            err = fmt.Errorf("internal error: %v", r)
        }
    }()
  
    return internalFunction(x, y), nil
}

// internalFunction might panic
func internalFunction(x, y int) int {
    if y == 0 {
        panic("division by zero")
    }
    return x / y
}
```

This approach keeps panics as an implementation detail inside your package.

## Understanding the Mechanics: How It Works Under the Hood

### Defer: The Hidden Stack

When a function executes, the Go runtime maintains a hidden stack of deferred function calls. Each time a defer statement executes:

1. The function and arguments are evaluated
2. A new entry is pushed onto the defer stack
3. When the function returns, each entry is popped off and executed

In pseudocode:

```
function someFunc() {
    deferStack = []
  
    // defer fmt.Println("First")
    evalArgs("First")
    deferStack.push(printlnWithArgs("First"))
  
    // defer fmt.Println("Second")
    evalArgs("Second")
    deferStack.push(printlnWithArgs("Second"))
  
    // Normal function execution
  
    // Function is about to return
    while deferStack not empty:
        fn = deferStack.pop()
        fn() // Execute deferred function
}
```

### Panic: The Unwinding Process

When a panic occurs, the Go runtime:

1. Stops normal execution
2. Starts unwinding the stack frame by frame
3. For each frame, executes any deferred functions
4. If no recover happens, prints the panic message and stack trace, then terminates

In pseudocode:

```
function handlePanic(panicValue) {
    currentFrame = getCurrentStackFrame()
  
    while currentFrame exists:
        executeDeferredFunctionsFor(currentFrame)
      
        // Check if any deferred function recovered
        if panicRecovered:
            return to normal execution
          
        currentFrame = currentFrame.caller
  
    // If we get here, nothing recovered
    printPanicAndStackTrace(panicValue)
    terminateProgram()
}
```

### Recover: Catching the Fall

When recover() is called:

1. If not in a panic state, it returns nil
2. If in a panic state:
   * Captures the panic value
   * Stops the unwinding process
   * Returns the panic value
   * Allows the deferred function to complete normally
   * Resumes normal execution after the defer statement

In pseudocode:

```
function recover() {
    if not inPanicState:
        return nil
  
    panicValue = currentPanic
    clearPanicState()
    return panicValue
}
```

## Conclusion: The Power of the Trio

Together, defer, panic, and recover form a robust error handling mechanism:

1. **Defer** ensures cleanup code always runs, simplifying resource management
2. **Panic** provides a way to react to exceptional errors
3. **Recover** allows controlled handling of those exceptional situations

This trio gives Go programs the ability to maintain clean, readable code while still handling exceptional conditions gracefully. While Go's primary error handling philosophy centers around explicit error checking, the defer-panic-recover trio addresses the exceptional cases where normal error handling isn't sufficient.

Understanding these mechanisms from first principles allows you to write more robust, reliable Go code that can gracefully handle unexpected situations while ensuring proper resource management.
