# Promise Error Propagation in Node.js: From First Principles

> Understanding how errors move through Promise chains is fundamental to writing robust asynchronous JavaScript code. This exploration will build your mental model from the ground up.

## 1. Promise Fundamentals: What Are We Really Working With?

Before diving into error propagation, let's understand what a Promise truly is at its core.

### The Promise Concept

> A Promise is an object representing the eventual completion (or failure) of an asynchronous operation and its resulting value.

Promises exist in one of three states:

* **Pending** : Initial state, neither fulfilled nor rejected
* **Fulfilled** : The operation completed successfully
* **Rejected** : The operation failed

Let's first see the creation of a basic Promise:

```javascript
// Creating a Promise that resolves after 1 second
const simplePromise = new Promise((resolve, reject) => {
  setTimeout(() => {
    resolve('Success!'); // Fulfills the promise
  }, 1000);
});

// Consuming the Promise
simplePromise
  .then(value => {
    console.log(value); // Outputs: "Success!"
  });
```

In this example, I'm creating a Promise that resolves after 1 second. The Promise constructor takes a function (called the "executor") with `resolve` and `reject` parameters. When `resolve()` is called, the Promise transitions from pending to fulfilled.

### Promise Chain Basics

Promises can be chained together, creating a sequence of asynchronous operations:

```javascript
const chainExample = new Promise((resolve, reject) => {
  resolve(1);
});

chainExample
  .then(value => {
    console.log(value); // 1
    return value + 1;
  })
  .then(value => {
    console.log(value); // 2
    return value + 1;
  })
  .then(value => {
    console.log(value); // 3
  });
```

Each `.then()` returns a new Promise that resolves with the return value of the callback. This is crucial for understanding how values (and errors) propagate through a chain.

## 2. Error Creation in Promises

Errors in Promises can occur in two ways:

### Explicit Rejection

```javascript
const explicitRejection = new Promise((resolve, reject) => {
  reject(new Error('Something went wrong'));
});

explicitRejection
  .catch(error => {
    console.error('Caught:', error.message); 
    // Outputs: "Caught: Something went wrong"
  });
```

Here, I explicitly reject the Promise using the `reject` function, passing an Error object.

### Thrown Exceptions

```javascript
const throwingPromise = new Promise((resolve, reject) => {
  throw new Error('Exception inside Promise executor');
});

throwingPromise
  .catch(error => {
    console.error('Caught:', error.message);
    // Outputs: "Caught: Exception inside Promise executor" 
  });
```

A thrown exception inside the Promise executor is automatically caught and converted to a rejection.

## 3. The Core of Error Propagation

> Error propagation in Promises follows a fundamental principle: a rejected Promise will skip all subsequent `.then()` handlers until it finds a `.catch()` handler.

This is the key insight that makes Promise error handling so powerful:

```javascript
Promise.resolve(1)
  .then(value => {
    throw new Error('Oops!');
    // The following line never executes:
    return value + 1;
  })
  .then(value => {
    // This handler is skipped entirely
    console.log('This will not run');
    return value + 1;
  })
  .catch(error => {
    // Error is caught here
    console.error('Caught:', error.message); 
    // Outputs: "Caught: Oops!"
    return 'recovered';
  })
  .then(value => {
    // Chain continues after catch
    console.log('After catch:', value); 
    // Outputs: "After catch: recovered"
  });
```

Let's break down what happens here:

1. The Promise resolves with value `1`
2. First `.then()` receives `1` but throws an error
3. Second `.then()` is skipped entirely
4. The `.catch()` handler receives the error
5. The chain continues with the value returned from `.catch()`

This is the essence of Promise error propagation. Errors "jump ahead" in the chain to the nearest error handler.

## 4. Error Recovery and Chain Continuation

After a `.catch()` handler runs, the Promise chain can continue normally:

```javascript
fetchData() // Assume this returns a Promise
  .then(data => {
    if (!data) throw new Error('No data');
    return processData(data);
  })
  .then(processed => {
    return formatResults(processed);
  })
  .catch(error => {
    console.error('Processing failed:', error);
    return getDefaultResults(); // Provide fallback data
  })
  .then(results => {
    // This runs with either the real results or default results
    displayResults(results);
  });
```

In this example, if any operation fails (fetchData, processData, or formatResults), the chain skips to the `.catch()` handler. The handler provides fallback data and the chain continues.

## 5. Errors in Nested Promises

Error propagation gets more complex with nested Promises:

```javascript
Promise.resolve()
  .then(() => {
    return new Promise((resolve, reject) => {
      reject(new Error('Nested rejection'));
    });
  })
  .then(() => {
    console.log('This will be skipped');
  })
  .catch(error => {
    console.error('Caught nested error:', error.message);
    // Outputs: "Caught nested error: Nested rejection"
  });
```

When a Promise returned from a `.then()` callback is rejected, that rejection propagates through the outer Promise chain.

This can get confusing with deeper nesting. Here's a more complex example:

```javascript
Promise.resolve()
  .then(() => {
    return Promise.resolve()
      .then(() => {
        throw new Error('Deeply nested error');
      })
      .then(() => {
        console.log('Never runs');
        return 'never returned';
      });
    // No catch here in the inner chain
  })
  .then(() => {
    console.log('This is skipped too');
  })
  .catch(error => {
    console.error('Outer catch:', error.message);
    // Outputs: "Outer catch: Deeply nested error"
  });
```

The error bubbles all the way up from the innermost Promise to the outermost `.catch()`. This automatic propagation across nested chains is powerful but can be hard to follow.

## 6. Common Error Propagation Patterns

### Pattern 1: The Final Catch

A common pattern is to have a single `.catch()` at the end of a chain to handle any errors:

```javascript
doStep1()
  .then(result1 => doStep2(result1))
  .then(result2 => doStep3(result2))
  .then(result3 => doStep4(result3))
  .then(result4 => {
    console.log('Operation complete:', result4);
  })
  .catch(error => {
    console.error('Operation failed:', error);
  });
```

If any step fails, the error jumps to the final `.catch()`.

### Pattern 2: Intermediate Error Handling

Sometimes you want to catch errors from specific operations:

```javascript
fetchUserData(userId)
  .then(userData => {
    try {
      const processed = riskyProcessing(userData);
      return processed;
    } catch (e) {
      // Handle synchronous errors locally
      console.warn('Processing error, using partial data:', e);
      return userData; // Continue with raw data instead
    }
  })
  .then(data => displayUserProfile(data))
  .catch(error => {
    // Handle any async errors or uncaught sync errors
    console.error('Failed to load user profile:', error);
    displayErrorMessage();
  });
```

This pattern combines synchronous try/catch with Promise `.catch()`.

### Pattern 3: Error Transformation

You can catch and transform errors to provide more context:

```javascript
fetchData(url)
  .then(response => {
    if (!response.ok) {
      // Create a more specific error
      throw new ApiError(
        `API returned ${response.status}`,
        response.status,
        url
      );
    }
    return response.json();
  })
  .then(data => processData(data))
  .catch(error => {
    if (error instanceof ApiError) {
      // Handle API-specific errors
      console.error(`API Error (${error.statusCode}):`, error.message);
      if (error.statusCode === 401) {
        redirectToLogin();
      }
    } else {
      // Handle other errors
      console.error('Unknown error:', error);
    }
  });
```

This example transforms HTTP errors into application-specific errors with more context.

## 7. Promise.all Error Propagation

`Promise.all()` has special error propagation behavior:

```javascript
const promises = [
  Promise.resolve(1),
  Promise.reject(new Error('One failed')),
  Promise.resolve(3)
];

Promise.all(promises)
  .then(results => {
    console.log('All succeeded:', results);
    // Never runs
  })
  .catch(error => {
    console.error('At least one failed:', error.message);
    // Outputs: "At least one failed: One failed"
  });
```

> Promise.all follows a "fail-fast" approach: if any Promise rejects, the entire operation rejects immediately, even if other Promises are still pending.

This behavior is useful when you need all operations to succeed, but can be limiting.

### Promise.allSettled for Error Collection

When you want to know the results of all Promises regardless of success or failure:

```javascript
const mixedPromises = [
  Promise.resolve('success 1'),
  Promise.reject(new Error('error 1')),
  Promise.resolve('success 2')
];

Promise.allSettled(mixedPromises)
  .then(results => {
    // results is an array of objects with status and value/reason
    const succeeded = results.filter(r => r.status === 'fulfilled');
    const failed = results.filter(r => r.status === 'rejected');
  
    console.log(`${succeeded.length} succeeded, ${failed.length} failed`);
    // Outputs: "2 succeeded, 1 failed"
  
    // Process successful results
    succeeded.forEach(s => console.log('Success:', s.value));
  
    // Process errors
    failed.forEach(f => console.log('Error:', f.reason));
  });
```

`Promise.allSettled()` never rejects; instead, it resolves with detailed information about all Promises.

## 8. The finally() Method and Error Propagation

The `.finally()` method runs regardless of success or failure:

```javascript
fetchData()
  .then(data => {
    return processData(data);
  })
  .catch(error => {
    console.error('Error:', error);
    throw error; // Re-throw to propagate further
  })
  .finally(() => {
    // This code always runs
    hideLoadingSpinner();
    closeConnection();
  });
```

Important properties of `.finally()`:

* It doesn't receive any arguments
* It doesn't change the value/error being propagated
* If it returns a Promise, the chain waits for it to settle

If `.finally()` throws an error, it replaces any previous error in the chain.

## 9. Advanced Error Propagation Techniques

### Selective Error Catching

You can catch only specific errors and re-throw others:

```javascript
fetchData()
  .then(data => processData(data))
  .catch(error => {
    if (error instanceof NetworkError) {
      // Handle network errors
      return getOfflineData();
    }
  
    // Re-throw other errors
    throw error;
  })
  .then(data => displayData(data))
  .catch(error => {
    // Handle any errors not caught above
    console.error('Fatal error:', error);
    showErrorScreen();
  });
```

This pattern allows for different error handling strategies based on error type.

### Aggregating Errors

For complex operations, you might want to collect multiple errors:

```javascript
function validateUserData(userData) {
  const errors = [];
  
  if (!userData.name) {
    errors.push(new ValidationError('name', 'Name is required'));
  }
  
  if (!userData.email) {
    errors.push(new ValidationError('email', 'Email is required'));
  } else if (!isValidEmail(userData.email)) {
    errors.push(new ValidationError('email', 'Email is invalid'));
  }
  
  if (errors.length > 0) {
    const aggregateError = new AggregateError(
      errors,
      'Validation failed'
    );
    return Promise.reject(aggregateError);
  }
  
  return Promise.resolve(userData);
}

// Usage
validateUserData(formData)
  .then(data => saveUser(data))
  .catch(error => {
    if (error instanceof AggregateError) {
      // Display all validation errors
      error.errors.forEach(e => {
        showFieldError(e.field, e.message);
      });
    } else {
      // Handle other errors
      showGeneralError(error);
    }
  });
```

This approach collects all errors rather than failing on the first one.

## 10. Common Error Propagation Mistakes

### Mistake 1: Forgotten Return

```javascript
// INCORRECT
fetchData()
  .then(data => {
    processData(data); // Missing return!
  })
  .then(result => {
    console.log(result); // Will be undefined!
  });

// CORRECT
fetchData()
  .then(data => {
    return processData(data);
  })
  .then(result => {
    console.log(result); // Properly receives the processed data
  });
```

Forgetting to return a value or Promise in a `.then()` callback will cause the next callback to receive `undefined`.

### Mistake 2: Swallowed Errors

```javascript
// INCORRECT - Error is caught but not handled
fetchData()
  .then(data => processData(data))
  .catch(error => {
    console.log('An error occurred'); // Error is swallowed
  })
  .then(result => {
    // This runs with result = undefined
    saveToDatabase(result); // Will likely cause another error
  });

// CORRECT
fetchData()
  .then(data => processData(data))
  .catch(error => {
    console.error('Processing error:', error);
    return getDefaultData(); // Provide fallback
  })
  .then(result => {
    // This runs with actual data or fallback data
    saveToDatabase(result);
  });
```

Without proper error handling or re-throwing, errors can silently disappear.

### Mistake 3: Async Function Confusion

```javascript
// INCORRECT
async function processUser(userId) {
  const userData = await fetchUser(userId);
  
  // No try/catch, error will escape the function
  const processedData = await processUserData(userData);
  
  return processedData;
}

// CORRECT
async function processUser(userId) {
  try {
    const userData = await fetchUser(userId);
    const processedData = await processUserData(userData);
    return processedData;
  } catch (error) {
    console.error('User processing failed:', error);
    return null; // Or throw or handle as appropriate
  }
}
```

With async/await, errors need explicit try/catch blocks or they'll cause the returned Promise to reject.

## 11. Best Practices for Promise Error Handling

> Always handle Promise rejections. Unhandled rejections can cause hard-to-debug issues and memory leaks.

1. **Use specific error types**

```javascript
class DatabaseError extends Error {
  constructor(message, code, query) {
    super(message);
    this.name = 'DatabaseError';
    this.code = code;
    this.query = query;
  }
}

function queryDatabase(query) {
  return db.execute(query)
    .catch(err => {
      throw new DatabaseError(
        `Query failed: ${err.message}`,
        err.code,
        query
      );
    });
}
```

2. **Set up global unhandled rejection handler**

```javascript
process.on('unhandledRejection', (reason, promise) => {
  console.error('Unhandled Rejection at:', promise);
  console.error('Reason:', reason);
  
  // Optional: terminate process
  // process.exit(1);
});
```

3. **Limit Promise nesting depth**

```javascript
// AVOID deep nesting
fetchUser()
  .then(user => {
    return fetchUserPermissions(user.id)
      .then(permissions => {
        return fetchRestrictedContent(permissions)
          .then(content => {
            // Too much nesting...
          });
      });
  });

// BETTER
fetchUser()
  .then(user => fetchUserPermissions(user.id))
  .then(permissions => fetchRestrictedContent(permissions))
  .then(content => {
    // Flat chain is easier to follow
  })
  .catch(error => {
    // One catch for the entire chain
  });
```

4. **Be consistent with error handling strategy**

Choose a consistent approach:

* Whether to use mostly `.catch()` or try/catch with async/await
* How to format error messages
* When to recover vs. when to propagate errors

## Conclusion

> Promise error propagation is a powerful mechanism that allows JavaScript to handle asynchronous errors in a structured, predictable way.

The key principles to remember:

1. Errors propagate automatically through Promise chains
2. `.then()` handlers are skipped when a Promise is rejected
3. `.catch()` handlers intercept errors and can recover the chain
4. Error handling strategies should be deliberate and consistent

By mastering these concepts, you can write robust asynchronous code that gracefully handles failures rather than crashing unexpectedly.
